Workbook
Name OLE_LINK3: 'COMPOSITION_old '!$D$24

Sheet use instructions
B3: 1. fill in the mandatory fields in the composition sheet
B4: 2. update all the green sheets with the latest database (download)

Sheet SoC screening tool ENV
A1: Guidance on the Biocidal Products Regulation
A2: Volume IV Environment - Assessment and Evaluation (Parts B + C)
A3: Version 2.0 October 2017
B7: Guidance on BPR: Vol IV Environment Parts B+C, Version 2.0 October 2017 identification of substances of concern | C7: screening tool
A8: ID SoC | B8: § 8.1 A SoC is a co-formulant in a biocidal product which meets at least one of the conditions specified in Article 3(f): * a substance classified as dangerous or that meets the criteria to be classified as dangerous according to Directive 67/548/EEC, and that is present in the biocidal product at a concentration leading the product to be regarded as dangerous within the meaning of Articles 5, 6 and 7 of Directive 1999/45/EC, or * a substance classified as hazardous or that meets the criteria for classification as hazardous according to Regulation (EC) No 1272/2008, and that is present in the biocidal product at a concentration leading the product to be regarded as hazardous within the meaning of that Regulation, * a substance which meets the criteria for being a persistent organic pollutant (POP) under Regulation (EC) No 850/2004, or which meets the criteria for being persistent, bio-accumulative and toxic (PBT) or very persistent and very bio-accumulative (vPvB) in accordance with Annex XIII to Regulation (EC) No 1907/2006; | C8: - check for presence of ENV classification (H'*) of the substance and the mixture - check if the substance is present on the list of suspected substances of high concern / show for which criterium (POP, PBT or vPvB)
A9: Other grounds for concern | B9: 1. Active substances (AS) from other product types (PTs) contained in the product for which a draft final Competent Authority Report (CAR, with an agreed risk assessment) is available. This criterion identifies other active substances in the biocidal product that act as co-formulants. Those substances should be regarded as SoCs because they potentially affect environmental organisms due to their intrinsic biological activity. They should be considered as SoCs if they are present in the biocidal product at a concentration ≥ 0.1%. ! This concentration limit is not applicable to PBT- or vPvB- substances and endocrine disrupting chemicals (EDs), as safe concentration limits cannot be derived for those substances. It needs to be checked whether this concentration limit is valid for the respective substance as highly toxic substances may contribute to the overall toxicity of the product even when contained to very small amounts in the product, i.e a co-formulant should be regarded as SoC if the PNEC of the respective substance is lower than the PNEC of the a.s. even though its concentration in the product is below the 0.1% criterion. exemptions are possible under the following condition: the substance is contained in Annex I of the BPR | C9: - check substance presence on the list 'ECHA list of bioicidal active substances' by CASnr - check if Annex I AS TODO: check yourself if the PNECS SoC < PNECS AS ; concentration > 0.1%
B10: 2. Substances that enhance the effect of the active substance in the product, e.g. synergists. For synergists, information/data shall be provided related to the interaction between the active substance and the synergist, not only for the synergist itself. For such substances, an appropriate evaluation of the risks posed by the active substance in the presence of the synergist rather than an evaluation of the risks posed by the synergist itself should be undertaken. A generic concentration cut-off value for the presence of a synergist in a product, applicable to all synergists cannot be specified. On a case-by-case basis, a synergist should be considered a SoC, if it is present at a concentration that enhances the toxicity of the active substance, as indicated by the available data. Furthermore, the hazard profile, potency and exposure potential of the substance enhancing the effects of the active substance should be taken into account. Further details on the identification of synergists can be found in section 10.2.3. Also diluents, (lipophilic) organic solvents and surfactants like e.g. naptha may influenc e the toxicity of a mixture by enhancing the bioavailability of the active substance(s) and should therefore be regarded carefully. In principle, all co-formulants need to be checked for a potential influence on the toxicity of the other product components. | C10: - ask for synergictic effects to the registration holder - check for synergists in tab synergists
B11: 3. Substances that have been included in the candidate list established in accordance with the REACH Regulation (1907/2006/EC, as amended), Article 57 (f) and 59(1) or fulfil the criteria for inclusion in the candidate list, if not already covered by the criteria of Article 3(f) of the BPR (see above). This criterion will capture, the clearly-defined SoCs specified in Article 3(f) of the BPR as well as endocrine disruptors (EDs) and PBT-substances which are not covered by Article 57 (d-e) of the REACH Regulation. | C11: see first criterium
B12: 4. Substances which meet two of the criteria for being PBT in accordance with Annex XIII to Regulation (EC) No 1907/2006, as amended.
B13: 5. Substances for which an Environmental Quality Standard (EQS) has been derived under Directive 2000/60/EC (Water Framework Directive; according to paragraph 67, Annex VI, BPR). | C13: - check EQS WFD database https://eur-lex.europa.eu/legal-content/EN/TXT/HTML/?uri=CELEX:02008L0105-20130913&from=EN
B15: exemptions are possible if the substances are contributing only to a very limited extent to the overall toxicity of the mixture (see section 10.2.2 as well as Appendix 9, Appendix 10 and Appendix 12) and are neither EDs nor PBT- or vPvB-substances. The causes leading to the (non-)classification of a substance as a substance of concern (SoC) need to be documented, i.e. for all substances present in a biocidal product it needs to be checked (and reported) whether they meet one of the criteria described above. It is up to the applicant to provide such an assessment to the evaluating CA.
B17: ca doc about limit 0.1%

Sheet COMPOSITION_old
F2: IF(ISNUMBER(MATCH(G7,'ECHA candidate SVHC 20230301'!D:D,0)),"TRUE","False") | Y2: HH | AE2: ENV | AK2: outcome screening
M3: outcome screening | N3: ENV. cat. 1 | O3: ENV. cat. 2 | P3: ENV. cat. 2 | Q3: ENV. cat. 2 | R3: ENV cat. 4 | S3: ENV cat. 5 | T3: ENV cat. 6 | U3: ENV cat. 4 | W3: ENV cat. 3 | X3: outcome screening | Y3: HH cat. 1 | Z3: HH cat. 2 | AA3: HH cat. 3 | AB3: HH cat. 4 | AC3: HH cat. 5 | AE3: ENV. cat. 1 | AF3: ENV. cat. 2 | AG3: ENV cat. 3 | AH3: ENV cat. 4 | AI3: ENV cat. 5 | AJ3: ENV cat. 6
F4: VLOOKUP(G7,'ECHA biocidal AS_20230301'!C6:H1473,6,FALSE) | N4: - | Y4: band A or B | Z4: band C | AA4: band C | AB4: band D | AC4: band C | AE4: -
N5: QuaLitative or QuaNitative | O5: QuaLitative or QuaNitative | P5: QuaLitative or QuaNitative | Q5: QuaLitative or QuaNitative | R5: QuaLitative or QuaNitative | S5: QuaLitative or QuaNitative | T5: QuaLitative or QuaNitative | U5: QuaLitative or QuaNitative | W5: QuaNitative | Y5: QuaLitative | Z5: QuaNitative | AA5: QuaNitative | AB5: QuaNitative | AC5: QuaNitative | AE5: QuaLitative or QuaNitative | AF5: QuaLitative or QuaNitative | AG5: QuaNitative | AH5: QuaLitative or QuaNitative | AI5: QuaLitative or QuaNitative | AJ5: QuaLitative or QuaNitative
B6: No | C6: Company | D6: Product | E6: Product classification | F6: Ingredient name | G6: CAS | H6: EC | I6: Classification from SDS | J6: Vapor pressure (>0.01 Pa Consexpo calcl.) | L6: Concentration (%) | M6: ID as possible SoC | N6: triggers ENV class | O6: Annex 1 AS | P6: lookup AS and NOT Annex I | Q6: AS + (conc > 0.1% or ED or PBT or PNEC < PNEC AS) | R6: lookup vPvB, PBT | S6: lookup B and T ccriteria | T6: lookup EQS list WFD | U6: lookup POP list | V6: lookup Ctgb list | W6: synergist | X6: Type of assessment (QN or QL) | Y6: triggers HH classif. | Z6: Active substance with CAR> 0.1% | AA6: Synergist | AB6: REACH SVHC (incl. PBT, vPvB), ED, CMR | AC6: OEL (mg/m3) | AD6: OEL reference: SCOEL or XX for country | AE6: Triggers ENV classification | AF6: Active substance with CAR> 0.1% (or if PNECSoC <PNECas also <0.1%) | AG6: Synergist | AH6: REACH SVHC (incl. PBT, vPvB) | AI6: 2 of 3 PBT criteria | AJ6: EQS water frame work directive | AK6: Type of assessment (QN or QL)
E7: H211-h101-EUH302 | G7: 87-69-4 | I7: H226-H404-EUH066 | M7: {=OR(P7:V7="true")} -> #N/A | N7: =IF(AND((COUNTIF(I7,"*H4*")),(COUNTIF($E$7,"*H4*"))),TRUE,FALSE) -> FALSE | O7: =VLOOKUP(G7,'ECHA biocidal AS'!C6:H1473,6,FALSE) -> #N/A | P7: =IF(AND(O7="false",(ISNUMBER(MATCH(G7,'ECHA biocidal AS'!C:C,0)))),"TRUE","False") -> #N/A | R7: =IF(ISNUMBER(MATCH(G7,'ECHA candidate SVHC'!D:D,0)),"TRUE","False") -> False | T7: =IF(ISNUMBER(MATCH(F7,'EQS WFD'!C:C,0)),"TRUE","False") -> False | U7: =IF(ISNUMBER(MATCH(G7,'ECHA POP'!D:D,0)),"TRUE","False") -> False | V7: =IF(ISNUMBER(MATCH(G7,'SoC_Ctgb 20181010'!C:C,0)),"TRUE","False") -> False
G8: 30507-70-1 | I8: n/a? (no SDS provided) | M8: {=OR(P8:V8="true")} -> TRUE | N8: =IF(AND((COUNTIF(I8,"*H4*")),(COUNTIF($E$7,"*H4*"))),TRUE,FALSE) -> FALSE | O8: =VLOOKUP(G8,'ECHA biocidal AS'!C7:H1474,6,FALSE) -> false | P8: =IF(AND(O8="false",(ISNUMBER(MATCH(G8,'ECHA biocidal AS'!C:C,0)))),"TRUE","False") -> TRUE | R8: =IF(ISNUMBER(MATCH(G8,'ECHA candidate SVHC'!D:D,0)),"TRUE","False") -> False | T8: =IF(ISNUMBER(MATCH(F8,'EQS WFD'!C:C,0)),"TRUE","False") -> False | U8: =IF(ISNUMBER(MATCH(G8,'ECHA POP'!D:D,0)),"TRUE","False") -> False | V8: =IF(ISNUMBER(MATCH(G8,'SoC_Ctgb 20181010'!C:C,0)),"TRUE","False") -> False
G9: 1166-46-7 | I9: H304-EUH066 | M9: {=OR(P9:V9="true")} -> #N/A | N9: =IF(AND((COUNTIF(I9,"*H4*")),(COUNTIF($E$7,"*H4*"))),TRUE,FALSE) -> FALSE | O9: =VLOOKUP(G9,'ECHA biocidal AS'!C8:H1475,6,FALSE) -> #N/A | P9: =IF(AND(O9="false",(ISNUMBER(MATCH(G9,'ECHA biocidal AS'!C:C,0)))),"TRUE","False") -> #N/A | R9: =IF(ISNUMBER(MATCH(G9,'ECHA candidate SVHC'!D:D,0)),"TRUE","False") -> False | T9: =IF(ISNUMBER(MATCH(F9,'EQS WFD'!C:C,0)),"TRUE","False") -> False | U9: =IF(ISNUMBER(MATCH(G9,'ECHA POP'!D:D,0)),"TRUE","False") -> False | V9: =IF(ISNUMBER(MATCH(G9,'SoC_Ctgb 20181010'!C:C,0)),"TRUE","False") -> False
G10: 64742-49-0 | I10: H304-EUH066 | M10: {=OR(P10:V10="true")} -> #N/A | N10: =IF(AND((COUNTIF(I10,"*H4*")),(COUNTIF($E$7,"*H4*"))),TRUE,FALSE) -> FALSE | O10: =VLOOKUP(G10,'ECHA biocidal AS'!C9:H1476,6,FALSE) -> #N/A | P10: =IF(AND(O10="false",(ISNUMBER(MATCH(G10,'ECHA biocidal AS'!C:C,0)))),"TRUE","False") -> #N/A | R10: =IF(ISNUMBER(MATCH(G10,'ECHA candidate SVHC'!D:D,0)),"TRUE","False") -> False | T10: =IF(ISNUMBER(MATCH(F10,'EQS WFD'!C:C,0)),"TRUE","False") -> False | U10: =IF(ISNUMBER(MATCH(G10,'ECHA POP'!D:D,0)),"TRUE","False") -> False | V10: =IF(ISNUMBER(MATCH(G10,'SoC_Ctgb 20181010'!C:C,0)),"TRUE","False") -> False
G11: 64742-49-0 | I11: h524-h485-h284 | M11: {=OR(P11:V11="true")} -> #N/A | N11: =IF(AND((COUNTIF(I11,"*H4*")),(COUNTIF($E$7,"*H4*"))),TRUE,FALSE) -> FALSE | O11: =VLOOKUP(G11,'ECHA biocidal AS'!C10:H1477,6,FALSE) -> #N/A | P11: =IF(AND(O11="false",(ISNUMBER(MATCH(G11,'ECHA biocidal AS'!C:C,0)))),"TRUE","False") -> #N/A | R11: =IF(ISNUMBER(MATCH(G11,'ECHA candidate SVHC'!D:D,0)),"TRUE","False") -> False | T11: =IF(ISNUMBER(MATCH(F11,'EQS WFD'!C:C,0)),"TRUE","False") -> False | U11: =IF(ISNUMBER(MATCH(G11,'ECHA POP'!D:D,0)),"TRUE","False") -> False | V11: =IF(ISNUMBER(MATCH(G11,'SoC_Ctgb 20181010'!C:C,0)),"TRUE","False") -> False
G12: 67-64-1 | I12: (no hazardus ingredient in SDS provided) | M12: {=OR(P12:V12="true")} -> #N/A | N12: =IF(AND((COUNTIF(I12,"*H4*")),(COUNTIF($E$7,"*H4*"))),TRUE,FALSE) -> FALSE | O12: =VLOOKUP(G12,'ECHA biocidal AS'!C11:H1478,6,FALSE) -> #N/A | P12: =IF(AND(O12="false",(ISNUMBER(MATCH(G12,'ECHA biocidal AS'!C:C,0)))),"TRUE","False") -> #N/A | R12: =IF(ISNUMBER(MATCH(G12,'ECHA candidate SVHC'!D:D,0)),"TRUE","False") -> False | T12: =IF(ISNUMBER(MATCH(F12,'EQS WFD'!C:C,0)),"TRUE","False") -> False | U12: =IF(ISNUMBER(MATCH(G12,'ECHA POP'!D:D,0)),"TRUE","False") -> False | V12: =IF(ISNUMBER(MATCH(G12,'SoC_Ctgb 20181010'!C:C,0)),"TRUE","False") -> False
G13: 29118-24-9 | I13: n/a? (no SDS provided) | M13: {=OR(P13:V13="true")} -> #N/A | N13: =IF(AND((COUNTIF(I13,"*H4*")),(COUNTIF($E$7,"*H4*"))),TRUE,FALSE) -> FALSE | O13: =VLOOKUP(G13,'ECHA biocidal AS'!C12:H1479,6,FALSE) -> #N/A | P13: =IF(AND(O13="false",(ISNUMBER(MATCH(G13,'ECHA biocidal AS'!C:C,0)))),"TRUE","False") -> #N/A | R13: =IF(ISNUMBER(MATCH(G13,'ECHA candidate SVHC'!D:D,0)),"TRUE","False") -> False | T13: =IF(ISNUMBER(MATCH(F13,'EQS WFD'!C:C,0)),"TRUE","False") -> False | U13: =IF(ISNUMBER(MATCH(G13,'ECHA POP'!D:D,0)),"TRUE","False") -> False | V13: =IF(ISNUMBER(MATCH(G13,'SoC_Ctgb 20181010'!C:C,0)),"TRUE","False") -> False
G14: 64742-49-0 | I14: n/a? (no SDS provided) | M14: {=OR(P14:V14="true")} -> #N/A | N14: =IF(AND((COUNTIF(I14,"*H4*")),(COUNTIF($E$7,"*H4*"))),TRUE,FALSE) -> FALSE | O14: =VLOOKUP(G14,'ECHA biocidal AS'!C13:H1480,6,FALSE) -> #N/A | P14: =IF(AND(O14="false",(ISNUMBER(MATCH(G14,'ECHA biocidal AS'!C:C,0)))),"TRUE","False") -> #N/A | R14: =IF(ISNUMBER(MATCH(G14,'ECHA candidate SVHC'!D:D,0)),"TRUE","False") -> False | T14: =IF(ISNUMBER(MATCH(F14,'EQS WFD'!C:C,0)),"TRUE","False") -> False | U14: =IF(ISNUMBER(MATCH(G14,'ECHA POP'!D:D,0)),"TRUE","False") -> False | V14: =IF(ISNUMBER(MATCH(G14,'SoC_Ctgb 20181010'!C:C,0)),"TRUE","False") -> False
G15: 64-17-5 | I15: H220 | M15: {=OR(P15:V15="true")} -> TRUE | N15: =IF(AND((COUNTIF(I15,"*H4*")),(COUNTIF($E$7,"*H4*"))),TRUE,FALSE) -> FALSE | O15: =VLOOKUP(G15,'ECHA biocidal AS'!C14:H1481,6,FALSE) -> false | P15: =IF(AND(O15="false",(ISNUMBER(MATCH(G15,'ECHA biocidal AS'!C:C,0)))),"TRUE","False") -> TRUE | R15: =IF(ISNUMBER(MATCH(G15,'ECHA candidate SVHC'!D:D,0)),"TRUE","False") -> False | T15: =IF(ISNUMBER(MATCH(F15,'EQS WFD'!C:C,0)),"TRUE","False") -> False | U15: =IF(ISNUMBER(MATCH(G15,'ECHA POP'!D:D,0)),"TRUE","False") -> False | V15: =IF(ISNUMBER(MATCH(G15,'SoC_Ctgb 20181010'!C:C,0)),"TRUE","False") -> False
I16: H220 mutagenic, carcinogenic | M16: {=OR(P16:V16="true")} -> #N/A | N16: =IF(AND((COUNTIF(I16,"*H4*")),(COUNTIF($E$7,"*H4*"))),TRUE,FALSE) -> FALSE | O16: =VLOOKUP(G16,'ECHA biocidal AS'!C15:H1482,6,FALSE) -> #N/A | P16: =IF(AND(O16="false",(ISNUMBER(MATCH(G16,'ECHA biocidal AS'!C:C,0)))),"TRUE","False") -> #N/A | R16: =IF(ISNUMBER(MATCH(G16,'ECHA candidate SVHC'!D:D,0)),"TRUE","False") -> False | T16: =IF(ISNUMBER(MATCH(F16,'EQS WFD'!C:C,0)),"TRUE","False") -> False | U16: =IF(ISNUMBER(MATCH(G16,'ECHA POP'!D:D,0)),"TRUE","False") -> False | V16: =IF(ISNUMBER(MATCH(G16,'SoC_Ctgb 20181010'!C:C,0)),"TRUE","False") -> False
I17: H220 mutagenic, carcinogenic | M17: {=OR(P17:V17="true")} -> #N/A | N17: =IF(AND((COUNTIF(I17,"*H4*")),(COUNTIF($E$7,"*H4*"))),TRUE,FALSE) -> FALSE | O17: =VLOOKUP(G17,'ECHA biocidal AS'!C16:H1483,6,FALSE) -> #N/A | P17: =IF(AND(O17="false",(ISNUMBER(MATCH(G17,'ECHA biocidal AS'!C:C,0)))),"TRUE","False") -> #N/A | R17: =IF(ISNUMBER(MATCH(G17,'ECHA candidate SVHC'!D:D,0)),"TRUE","False") -> False | T17: =IF(ISNUMBER(MATCH(F17,'EQS WFD'!C:C,0)),"TRUE","False") -> False | U17: =IF(ISNUMBER(MATCH(G17,'ECHA POP'!D:D,0)),"TRUE","False") -> False | V17: =IF(ISNUMBER(MATCH(G17,'SoC_Ctgb 20181010'!C:C,0)),"TRUE","False") -> False
I18: H225-H304-H315-H336-H411 | M18: {=OR(P18:V18="true")} -> #N/A | N18: =IF(AND((COUNTIF(I18,"*H4*")),(COUNTIF($E$7,"*H4*"))),TRUE,FALSE) -> FALSE | O18: =VLOOKUP(G18,'ECHA biocidal AS'!C17:H1484,6,FALSE) -> #N/A | P18: =IF(AND(O18="false",(ISNUMBER(MATCH(G18,'ECHA biocidal AS'!C:C,0)))),"TRUE","False") -> #N/A | R18: =IF(ISNUMBER(MATCH(G18,'ECHA candidate SVHC'!D:D,0)),"TRUE","False") -> False | T18: =IF(ISNUMBER(MATCH(F18,'EQS WFD'!C:C,0)),"TRUE","False") -> False | U18: =IF(ISNUMBER(MATCH(G18,'ECHA POP'!D:D,0)),"TRUE","False") -> False | V18: =IF(ISNUMBER(MATCH(G18,'SoC_Ctgb 20181010'!C:C,0)),"TRUE","False") -> False
M19: {=OR(P19:V19="true")} -> #N/A | N19: =IF(AND((COUNTIF(I19,"*H4*")),(COUNTIF($E$7,"*H4*"))),TRUE,FALSE) -> FALSE | O19: =VLOOKUP(G19,'ECHA biocidal AS'!C18:H1485,6,FALSE) -> #N/A | P19: =IF(AND(O19="false",(ISNUMBER(MATCH(G19,'ECHA biocidal AS'!C:C,0)))),"TRUE","False") -> #N/A | R19: =IF(ISNUMBER(MATCH(G19,'ECHA candidate SVHC'!D:D,0)),"TRUE","False") -> False | T19: =IF(ISNUMBER(MATCH(F19,'EQS WFD'!C:C,0)),"TRUE","False") -> False | U19: =IF(ISNUMBER(MATCH(G19,'ECHA POP'!D:D,0)),"TRUE","False") -> False | V19: =IF(ISNUMBER(MATCH(G19,'SoC_Ctgb 20181010'!C:C,0)),"TRUE","False") -> False
M20: {=OR(P20:V20="true")} -> #N/A | N20: =IF(AND((COUNTIF(I20,"*H4*")),(COUNTIF($E$7,"*H4*"))),TRUE,FALSE) -> FALSE | O20: =VLOOKUP(G20,'ECHA biocidal AS'!C19:H1486,6,FALSE) -> #N/A | P20: =IF(AND(O20="false",(ISNUMBER(MATCH(G20,'ECHA biocidal AS'!C:C,0)))),"TRUE","False") -> #N/A | R20: =IF(ISNUMBER(MATCH(G20,'ECHA candidate SVHC'!D:D,0)),"TRUE","False") -> False | T20: =IF(ISNUMBER(MATCH(F20,'EQS WFD'!C:C,0)),"TRUE","False") -> False | U20: =IF(ISNUMBER(MATCH(G20,'ECHA POP'!D:D,0)),"TRUE","False") -> False | V20: =IF(ISNUMBER(MATCH(G20,'SoC_Ctgb 20181010'!C:C,0)),"TRUE","False") -> False
M21: {=OR(P21:V21="true")} -> #N/A | N21: =IF(AND((COUNTIF(I21,"*H4*")),(COUNTIF($E$7,"*H4*"))),TRUE,FALSE) -> FALSE | O21: =VLOOKUP(G21,'ECHA biocidal AS'!C20:H1487,6,FALSE) -> #N/A | P21: =IF(AND(O21="false",(ISNUMBER(MATCH(G21,'ECHA biocidal AS'!C:C,0)))),"TRUE","False") -> #N/A | R21: =IF(ISNUMBER(MATCH(G21,'ECHA candidate SVHC'!D:D,0)),"TRUE","False") -> False | T21: =IF(ISNUMBER(MATCH(F21,'EQS WFD'!C:C,0)),"TRUE","False") -> False | U21: =IF(ISNUMBER(MATCH(G21,'ECHA POP'!D:D,0)),"TRUE","False") -> False | V21: =IF(ISNUMBER(MATCH(G21,'SoC_Ctgb 20181010'!C:C,0)),"TRUE","False") -> False
M22: {=OR(P22:V22="true")} -> #N/A | N22: =IF(AND((COUNTIF(I22,"*H4*")),(COUNTIF($E$7,"*H4*"))),TRUE,FALSE) -> FALSE | O22: =VLOOKUP(G22,'ECHA biocidal AS'!C21:H1488,6,FALSE) -> #N/A | P22: =IF(AND(O22="false",(ISNUMBER(MATCH(G22,'ECHA biocidal AS'!C:C,0)))),"TRUE","False") -> #N/A | R22: =IF(ISNUMBER(MATCH(G22,'ECHA candidate SVHC'!D:D,0)),"TRUE","False") -> False | T22: =IF(ISNUMBER(MATCH(F22,'EQS WFD'!C:C,0)),"TRUE","False") -> False | U22: =IF(ISNUMBER(MATCH(G22,'ECHA POP'!D:D,0)),"TRUE","False") -> False | V22: =IF(ISNUMBER(MATCH(G22,'SoC_Ctgb 20181010'!C:C,0)),"TRUE","False") -> False
M23: {=OR(P23:V23="true")} -> #N/A | N23: =IF(AND((COUNTIF(I23,"*H4*")),(COUNTIF($E$7,"*H4*"))),TRUE,FALSE) -> FALSE | O23: =VLOOKUP(G23,'ECHA biocidal AS'!C22:H1489,6,FALSE) -> #N/A | P23: =IF(AND(O23="false",(ISNUMBER(MATCH(G23,'ECHA biocidal AS'!C:C,0)))),"TRUE","False") -> #N/A | R23: =IF(ISNUMBER(MATCH(G23,'ECHA candidate SVHC'!D:D,0)),"TRUE","False") -> False | T23: =IF(ISNUMBER(MATCH(F23,'EQS WFD'!C:C,0)),"TRUE","False") -> False | U23: =IF(ISNUMBER(MATCH(G23,'ECHA POP'!D:D,0)),"TRUE","False") -> False | V23: =IF(ISNUMBER(MATCH(G23,'SoC_Ctgb 20181010'!C:C,0)),"TRUE","False") -> False
B24: BP1 | C24: P&G | D24: Febreze | F24: Bardac™ 2270 E | G24: 68424-95-3 | H24: 215-185-5 | J24: - | K24: Pure: | L24: 0.47 | M24: {=OR(P24:V24="true")} -> TRUE | N24: =IF(AND((COUNTIF(I24,"*H4*")),(COUNTIF($E$7,"*H4*"))),TRUE,FALSE) -> FALSE | O24: =VLOOKUP(G24,'ECHA biocidal AS'!C23:H1490,6,FALSE) -> false | P24: =IF(AND(O24="false",(ISNUMBER(MATCH(G24,'ECHA biocidal AS'!C:C,0)))),"TRUE","False") -> TRUE | R24: =IF(ISNUMBER(MATCH(G24,'ECHA candidate SVHC'!D:D,0)),"TRUE","False") -> False | T24: =IF(ISNUMBER(MATCH(F24,'EQS WFD'!C:C,0)),"TRUE","False") -> False | U24: =IF(ISNUMBER(MATCH(G24,'ECHA POP'!D:D,0)),"TRUE","False") -> False | V24: =IF(ISNUMBER(MATCH(G24,'SoC_Ctgb 20181010'!C:C,0)),"TRUE","False") -> False
G25: 107-21-1 | H25: 200-675-3 | K25: 0.0033 | M25: {=OR(P25:V25="true")} -> #N/A | N25: =IF(AND((COUNTIF(I25,"*H4*")),(COUNTIF($E$7,"*H4*"))),TRUE,FALSE) -> FALSE | O25: =VLOOKUP(G25,'ECHA biocidal AS'!C24:H1491,6,FALSE) -> #N/A | P25: =IF(AND(O25="false",(ISNUMBER(MATCH(G25,'ECHA biocidal AS'!C:C,0)))),"TRUE","False") -> #N/A | R25: =IF(ISNUMBER(MATCH(G25,'ECHA candidate SVHC'!D:D,0)),"TRUE","False") -> False | T25: =IF(ISNUMBER(MATCH(F25,'EQS WFD'!C:C,0)),"TRUE","False") -> False | U25: =IF(ISNUMBER(MATCH(G25,'ECHA POP'!D:D,0)),"TRUE","False") -> False | V25: =IF(ISNUMBER(MATCH(G25,'SoC_Ctgb 20181010'!C:C,0)),"TRUE","False") -> False
F26: Neutral 96%v Ethanol - Euro Denaturant | G26: 64-17-5 | H26: 205-623-3 | K26: TC content: | L26: 1.04 | M26: {=OR(P26:V26="true")} -> TRUE | N26: =IF(AND((COUNTIF(I26,"*H4*")),(COUNTIF($E$7,"*H4*"))),TRUE,FALSE) -> FALSE | O26: =VLOOKUP(G26,'ECHA biocidal AS'!C25:H1492,6,FALSE) -> false | P26: =IF(AND(O26="false",(ISNUMBER(MATCH(G26,'ECHA biocidal AS'!C:C,0)))),"TRUE","False") -> TRUE | R26: =IF(ISNUMBER(MATCH(G26,'ECHA candidate SVHC'!D:D,0)),"TRUE","False") -> False | T26: =IF(ISNUMBER(MATCH(F26,'EQS WFD'!C:C,0)),"TRUE","False") -> False | U26: =IF(ISNUMBER(MATCH(G26,'ECHA POP'!D:D,0)),"TRUE","False") -> False | V26: =IF(ISNUMBER(MATCH(G26,'SoC_Ctgb 20181010'!C:C,0)),"TRUE","False") -> False
F27: Silwet L-7600 | G27: 68938-54-5 | K27: =K25/0.908 -> 0.0036343612 | L27: 0.1 | M27: {=OR(P27:V27="true")} -> #N/A | N27: =IF(AND((COUNTIF(I27,"*H4*")),(COUNTIF($E$7,"*H4*"))),TRUE,FALSE) -> FALSE | O27: =VLOOKUP(G27,'ECHA biocidal AS'!C26:H1493,6,FALSE) -> #N/A | P27: =IF(AND(O27="false",(ISNUMBER(MATCH(G27,'ECHA biocidal AS'!C:C,0)))),"TRUE","False") -> #N/A | R27: =IF(ISNUMBER(MATCH(G27,'ECHA candidate SVHC'!D:D,0)),"TRUE","False") -> False | T27: =IF(ISNUMBER(MATCH(F27,'EQS WFD'!C:C,0)),"TRUE","False") -> False | U27: =IF(ISNUMBER(MATCH(G27,'ECHA POP'!D:D,0)),"TRUE","False") -> False | V27: =IF(ISNUMBER(MATCH(G27,'SoC_Ctgb 20181010'!C:C,0)),"TRUE","False") -> False
F28: Maleic Acid Solution- 30% | G28: 110-16-7 | H28: 203-473-3 | K28: =0.2*L24 -> 0.094 | L28: 0.2 | M28: {=OR(P28:V28="true")} -> #N/A | N28: =IF(AND((COUNTIF(I28,"*H4*")),(COUNTIF($E$7,"*H4*"))),TRUE,FALSE) -> FALSE | O28: =VLOOKUP(G28,'ECHA biocidal AS'!C27:H1494,6,FALSE) -> #N/A | P28: =IF(AND(O28="false",(ISNUMBER(MATCH(G28,'ECHA biocidal AS'!C:C,0)))),"TRUE","False") -> #N/A | R28: =IF(ISNUMBER(MATCH(G28,'ECHA candidate SVHC'!D:D,0)),"TRUE","False") -> False | T28: =IF(ISNUMBER(MATCH(F28,'EQS WFD'!C:C,0)),"TRUE","False") -> False | U28: =IF(ISNUMBER(MATCH(G28,'ECHA POP'!D:D,0)),"TRUE","False") -> False | V28: =IF(ISNUMBER(MATCH(G28,'SoC_Ctgb 20181010'!C:C,0)),"TRUE","False") -> False
F29: ACID CITRIC IN HOUSE | G29: 77-92-9 | H29: 206-738-1 | L29: 0.03 | M29: {=OR(P29:V29="true")} -> TRUE | N29: =IF(AND((COUNTIF(I29,"*H4*")),(COUNTIF($E$7,"*H4*"))),TRUE,FALSE) -> FALSE | O29: =VLOOKUP(G29,'ECHA biocidal AS'!C28:H1495,6,FALSE) -> false | P29: =IF(AND(O29="false",(ISNUMBER(MATCH(G29,'ECHA biocidal AS'!C:C,0)))),"TRUE","False") -> TRUE | R29: =IF(ISNUMBER(MATCH(G29,'ECHA candidate SVHC'!D:D,0)),"TRUE","False") -> False | T29: =IF(ISNUMBER(MATCH(F29,'EQS WFD'!C:C,0)),"TRUE","False") -> False | U29: =IF(ISNUMBER(MATCH(G29,'ECHA POP'!D:D,0)),"TRUE","False") -> False | V29: =IF(ISNUMBER(MATCH(G29,'SoC_Ctgb 20181010'!C:C,0)),"TRUE","False") -> False
F30: Emulan® ELH 60 (90% Active Solution of PEG60 Hydrogenated Caster Oil) | G30: 61788-85-0 | L30: 2.2 | M30: {=OR(P30:V30="true")} -> #N/A | N30: =IF(AND((COUNTIF(I30,"*H4*")),(COUNTIF($E$7,"*H4*"))),TRUE,FALSE) -> FALSE | O30: =VLOOKUP(G30,'ECHA biocidal AS'!C29:H1496,6,FALSE) -> #N/A | P30: =IF(AND(O30="false",(ISNUMBER(MATCH(G30,'ECHA biocidal AS'!C:C,0)))),"TRUE","False") -> #N/A | R30: =IF(ISNUMBER(MATCH(G30,'ECHA candidate SVHC'!D:D,0)),"TRUE","False") -> False | T30: =IF(ISNUMBER(MATCH(F30,'EQS WFD'!C:C,0)),"TRUE","False") -> False | U30: =IF(ISNUMBER(MATCH(G30,'ECHA POP'!D:D,0)),"TRUE","False") -> False | V30: =IF(ISNUMBER(MATCH(G30,'SoC_Ctgb 20181010'!C:C,0)),"TRUE","False") -> False
F31: DOWANOL™ EPh6 Glycol Ether | G31: 9004-78-8 | L31: 2 | M31: {=OR(P31:V31="true")} -> #N/A | N31: =IF(AND((COUNTIF(I31,"*H4*")),(COUNTIF($E$7,"*H4*"))),TRUE,FALSE) -> FALSE | O31: =VLOOKUP(G31,'ECHA biocidal AS'!C30:H1497,6,FALSE) -> #N/A | P31: =IF(AND(O31="false",(ISNUMBER(MATCH(G31,'ECHA biocidal AS'!C:C,0)))),"TRUE","False") -> #N/A | R31: =IF(ISNUMBER(MATCH(G31,'ECHA candidate SVHC'!D:D,0)),"TRUE","False") -> False | T31: =IF(ISNUMBER(MATCH(F31,'EQS WFD'!C:C,0)),"TRUE","False") -> False | U31: =IF(ISNUMBER(MATCH(G31,'ECHA POP'!D:D,0)),"TRUE","False") -> False | V31: =IF(ISNUMBER(MATCH(G31,'SoC_Ctgb 20181010'!C:C,0)),"TRUE","False") -> False
F32: CAUSTIC SODA LIQUOR | G32: 1310-73-2 | H32: 500-147-5 | L32: 0.9 | M32: {=OR(P32:V32="true")} -> #N/A | N32: =IF(AND((COUNTIF(I32,"*H4*")),(COUNTIF($E$7,"*H4*"))),TRUE,FALSE) -> FALSE | O32: =VLOOKUP(G32,'ECHA biocidal AS'!C31:H1498,6,FALSE) -> #N/A | P32: =IF(AND(O32="false",(ISNUMBER(MATCH(G32,'ECHA biocidal AS'!C:C,0)))),"TRUE","False") -> #N/A | R32: =IF(ISNUMBER(MATCH(G32,'ECHA candidate SVHC'!D:D,0)),"TRUE","False") -> False | T32: =IF(ISNUMBER(MATCH(F32,'EQS WFD'!C:C,0)),"TRUE","False") -> False | U32: =IF(ISNUMBER(MATCH(G32,'ECHA POP'!D:D,0)),"TRUE","False") -> False | V32: =IF(ISNUMBER(MATCH(G32,'SoC_Ctgb 20181010'!C:C,0)),"TRUE","False") -> False
F33: CAVASOL W7 HP TL | G33: 128446-35-5 | L33: 0.625 | M33: {=OR(P33:V33="true")} -> #N/A | N33: =IF(AND((COUNTIF(I33,"*H4*")),(COUNTIF($E$7,"*H4*"))),TRUE,FALSE) -> FALSE | O33: =VLOOKUP(G33,'ECHA biocidal AS'!C32:H1499,6,FALSE) -> #N/A | P33: =IF(AND(O33="false",(ISNUMBER(MATCH(G33,'ECHA biocidal AS'!C:C,0)))),"TRUE","False") -> #N/A | R33: =IF(ISNUMBER(MATCH(G33,'ECHA candidate SVHC'!D:D,0)),"TRUE","False") -> False | T33: =IF(ISNUMBER(MATCH(F33,'EQS WFD'!C:C,0)),"TRUE","False") -> False | U33: =IF(ISNUMBER(MATCH(G33,'ECHA POP'!D:D,0)),"TRUE","False") -> False | V33: =IF(ISNUMBER(MATCH(G33,'SoC_Ctgb 20181010'!C:C,0)),"TRUE","False") -> False
B34: BP2 | F34: Halosolve-D 463478 | G34: mixture | J34: - | L34: 0.021 | M34: {=OR(P34:V34="true")} -> #N/A | N34: =IF(AND((COUNTIF(I34,"*H4*")),(COUNTIF($E$7,"*H4*"))),TRUE,FALSE) -> FALSE | O34: =VLOOKUP(G34,'ECHA biocidal AS'!C33:H1500,6,FALSE) -> #N/A | P34: =IF(AND(O34="false",(ISNUMBER(MATCH(G34,'ECHA biocidal AS'!C:C,0)))),"TRUE","False") -> #N/A | R34: =IF(ISNUMBER(MATCH(G34,'ECHA candidate SVHC'!D:D,0)),"TRUE","False") -> False | T34: =IF(ISNUMBER(MATCH(F34,'EQS WFD'!C:C,0)),"TRUE","False") -> False | U34: =IF(ISNUMBER(MATCH(G34,'ECHA POP'!D:D,0)),"TRUE","False") -> False | V34: =IF(ISNUMBER(MATCH(G34,'SoC_Ctgb 20181010'!C:C,0)),"TRUE","False") -> False
F35: perfume group | G35: mixture | H35: 420-920-1 | L35: 0.45 | M35: {=OR(P35:V35="true")} -> #N/A | N35: =IF(AND((COUNTIF(I35,"*H4*")),(COUNTIF($E$7,"*H4*"))),TRUE,FALSE) -> FALSE | O35: =VLOOKUP(G35,'ECHA biocidal AS'!C34:H1501,6,FALSE) -> #N/A | P35: =IF(AND(O35="false",(ISNUMBER(MATCH(G35,'ECHA biocidal AS'!C:C,0)))),"TRUE","False") -> #N/A | R35: =IF(ISNUMBER(MATCH(G35,'ECHA candidate SVHC'!D:D,0)),"TRUE","False") -> False | T35: =IF(ISNUMBER(MATCH(F35,'EQS WFD'!C:C,0)),"TRUE","False") -> False | U35: =IF(ISNUMBER(MATCH(G35,'ECHA POP'!D:D,0)),"TRUE","False") -> False | V35: =IF(ISNUMBER(MATCH(G35,'SoC_Ctgb 20181010'!C:C,0)),"TRUE","False") -> False
F36: water | G36: 7732-18-5 | H36: 231-791-2 | L36: =100-SUM(L24:L35) -> 91.964 | M36: {=OR(P36:V36="true")} -> #N/A | N36: =IF(AND((COUNTIF(I36,"*H4*")),(COUNTIF($E$7,"*H4*"))),TRUE,FALSE) -> FALSE | O36: =VLOOKUP(G36,'ECHA biocidal AS'!C35:H1502,6,FALSE) -> #N/A | P36: =IF(AND(O36="false",(ISNUMBER(MATCH(G36,'ECHA biocidal AS'!C:C,0)))),"TRUE","False") -> #N/A | R36: =IF(ISNUMBER(MATCH(G36,'ECHA candidate SVHC'!D:D,0)),"TRUE","False") -> False | T36: =IF(ISNUMBER(MATCH(F36,'EQS WFD'!C:C,0)),"TRUE","False") -> False | U36: =IF(ISNUMBER(MATCH(G36,'ECHA POP'!D:D,0)),"TRUE","False") -> False | V36: =IF(ISNUMBER(MATCH(G36,'SoC_Ctgb 20181010'!C:C,0)),"TRUE","False") -> False
V37: =IF(ISNUMBER(MATCH(G37,'SoC_Ctgb 20181010'!C:C,0)),"TRUE","False") -> False
V38: =IF(ISNUMBER(MATCH(G38,'SoC_Ctgb 20181010'!C:C,0)),"TRUE","False") -> False
V39: =IF(ISNUMBER(MATCH(G39,'SoC_Ctgb 20181010'!C:C,0)),"TRUE","False") -> False
F46: substance classified as dangerous and leading to classification of the product to be regarded as dangerous
F47: substance meeting requirements as POP, vPvB or PBT
...

Sheet COMPOSITION
D2: insert date | E2: 45901
D3: insert meta/BPF name
D4: insert meta/BPF classification
D5: select PT: | E5: PT02-Disinfectants and algaecides not intended for direct application to humans or animals | M5: outcome screening | N5: HH cat. 1 | P5: HH cat. 2 | S5: HH cat. 3 | T5: HH cat. 4 | V5: HH cat. 5 | X5: outcome screening | Y5: A SoC is a co-formulant in a biocidal product which meets at least one of the conditions specified in Article 3(f): * a substance classified as dangerous according to Directive 67/548/EEC * a substance classified as hazardous according to Regulation (EC) No 1272/2008, and that is present in the biocidal product at a concentration leading the product to be regarded as hazardous within the meaning of that Regulation, | AA5: A SoC is a co-formulant in a biocidal product which meets at least one of the conditions specified in Article 3(f): accumulative and toxic (PBT) or very persistent and very bio-accumulative (vPvB) in accordance with Annex XIII to Regulation (EC) No 1907/2006; | AD5: Active substances (AS) from other product types (PTs) contained in the product for which a (draft) final Competent Authority Report (CAR, with an agreed risk assessment) is available. | AG5: Substances which meet two of the criteria for being PBT in accordance with Annex XIII to Regulation (EC) No 1907/2006, as amended. | AH5: Substances for which an Environmental Quality Standard (EQS) has been derived under Directive 2000/60/EC (Water Framework Directive; according to paragraph 67, Annex VI, BPR). | AI5: Substances that enhance the effect of the active substance in the product, e.g. synergists. For synergists, information/data shall be provided related to the interaction between the active substance and the synergist, not only for the synergist itself. For such substances, an appropriate evaluation of the risks posed by the active substance in the presence of the synergist rather than an evaluation of the risks posed by the synergist itself should be undertaken. A generic concentration cut-off value for the presence of a synergist in a product, applicable to all synergists cannot be specified. On a case-by-case basis, a synergist should be considered a SoC, if it is present at a concentration that enhances the toxicity of the active substance, as indicated by the available data. Furthermore, the hazard profile, potency and exposure potential of the substance enhancing the effects of the active substance should be taken into account. Further details on the identification of synergists can be found in section 10.2.3. Also diluents, (lipophilic) organic solvents and surfactants like e.g. naptha may influenc e the toxicity of a mixture by enhancing the bioavailability of the active substance(s) and should therefore be regarded carefully. In principle, all co-formulants need to be checked for a potential influence on the toxicity of the other product components.
M6: HUMAN HEALTH | N6: band A or B | P6: band C | S6: band C | T6: band D | V6: band C | X6: ENVIRONMENT
D7: insert below the composition split into components AND the CASnr + concentration of each substance | N7: QuaLitative | P7: QuaNtitative | S7: QuaNitative | T7: QuaNtitative | V7: QuaNtitative
B8: No | D8: RM SDS | E8: Ingredient name | F8: CAS | G8: EC | H8: Vapor pressure (>0.01 Pa Consexpo) | I8: WC concentration in mixture | J8: M-factor | K8: classification | L8: Concentration (%) | M8: ID as possible SoC | N8: HH classif | O8: triggers HH class (to check manually) | P8: Annex 1 AS | Q8: existing AS and not Annex 1 | R8: approved AS or with draft final CAR | S8: Synergist (to check manually) | T8: REACH SVHC - PBT, vPvB / ED / CMR | U8: Reason for inclusion | V8: OEL (mg/m3) (to check manually) | W8: Reference: SCOEL document number | X8: ID as possible SoC | Y8: ingredient & mixture have ENV class | Z8: triggers ENV class (based on mixture rules) | AA8: lookup POP in POP list | AB8: lookup vPvB, PBT in SVHC list | AC8: return PBT or vPvB in PBT list | AD8: Annex 1 AS | AE8: existing AS and not Annex 1 | AF8: approved AS or with draft final CAR | AG8: lookup B and T criteria | AH8: lookup EQS list WFD | AI8: Synergist to check manually | AJ8: Ctgb sheet (to IGNORE)
B9: BP1 | F9: 50-00-0 | L9: 3 | M9: =IF(COUNTIF(N9:W9,TRUE)>0,TRUE,"Not Found") -> TRUE | N9: =IF(AND((COUNTIF($E$4,"*H3*")),(COUNTIF(K9,"*H3*"))),TRUE,FALSE) -> FALSE | P9: =AD9 -> FALSE | Q9: =AE9 -> TRUE | R9: =AF9 -> TRUE | T9: =AC9 -> FALSE | U9: =AC9 -> FALSE | W9: {=IF(ISBLANK(F9),"FALSE",IFERROR((VLOOKUP(TRIM(F9),TRIM(SCOEL!$B$12:$E$400),3,"FALSE")),"FALSE"))} -> REC 125 | X9: =IF(COUNTIF(Z9:AI9,TRUE)>0,TRUE,"Not Found") -> TRUE | Y9: =IF(AND((COUNTIF($E$4,"*H4*")),(COUNTIF(K9,"*H4*"))),TRUE,FALSE) -> FALSE | Z9: =IF(COUNTIF(K9,"*H410*"),IF(J9*L9>25,"Cat. 1","not classified"),IF(COUNTIF(K9,"*H411*"),IF(L9>=25,"Cat. 2","not classified"),"geen H411")) -> geen H411 | AA9: =IF(ISNUMBER(MATCH(F9,'ECHA POP'!D:D,0)),TRUE,FALSE) -> FALSE | AB9: =IF(ISNUMBER(MATCH(F9,'ECHA candidate SVHC'!D:D,0)),TRUE,FALSE) -> FALSE | AC9: =IF(ISNUMBER(MATCH(F9,'ECHA PBT'!D:D,0)),TRUE,FALSE) -> FALSE | AD9: {=IF(ISNUMBER(MATCH(F9, _xlfn._xlws.FILTER('ECHA biocidal AS'!C:C, 'ECHA biocidal AS'!H:H="true"), 0)), "yes", FALSE)} -> FALSE | AE9: =IF(AND(AD9=FALSE,(ISNUMBER(MATCH(F9,'ECHA biocidal AS'!C:C,0)))),TRUE,FALSE) -> TRUE | AF9: {=IF(ISNUMBER(MATCH(F9, _xlfn._xlws.FILTER('ECHA biocidal AS'!C:C, 'ECHA biocidal AS'!M:M="Approved"), 0)), TRUE, FALSE)} -> TRUE | AH9: =IF(ISNUMBER(MATCH(F9,'EQS WFD'!D:D,0)),TRUE,FALSE) -> FALSE | AJ9: {=IF(AND(AE9=FALSE,ISNUMBER(MATCH(G9, _xlfn._xlws.FILTER('ECHA biocidal AS'!D:D, 'ECHA biocidal AS'!N:N="Approved"), 0))), TRUE, FALSE)} -> FALSE
F10: 64-17-5 | L10: 6 | M10: =IF(COUNTIF(N10:W10,TRUE)>0,TRUE,"Not Found") -> TRUE | N10: =IF(AND((COUNTIF($E$4,"*H3*")),(COUNTIF(K10,"*H3*"))),TRUE,FALSE) -> FALSE | P10: =AD10 -> FALSE | Q10: =AE10 -> TRUE | R10: =AF10 -> FALSE | T10: =AC10 -> FALSE | U10: =AD10 -> FALSE | W10: {=IF(ISBLANK(F10),"FALSE",IFERROR((VLOOKUP(TRIM(F10),TRIM(SCOEL!$B$12:$E$400),3,"FALSE")),"FALSE"))} -> FALSE | X10: =IF(COUNTIF(Z10:AI10,TRUE)>0,TRUE,"Not Found") -> TRUE | Y10: =IF(AND((COUNTIF($E$4,"*H4*")),(COUNTIF(K10,"*H4*"))),TRUE,FALSE) -> FALSE | Z10: =IF(COUNTIF(K10,"*H410*"),IF(J10*L10>25,"Cat. 1","not classified"),IF(COUNTIF(K10,"*H411*"),IF(L10>=25,"Cat. 2","not classified"),"geen H411")) -> geen H411 | AA10: =IF(ISNUMBER(MATCH(F10,'ECHA POP'!D:D,0)),TRUE,FALSE) -> FALSE | AB10: =IF(ISNUMBER(MATCH(F10,'ECHA candidate SVHC'!D:D,0)),TRUE,FALSE) -> FALSE | AC10: =IF(ISNUMBER(MATCH(F10,'ECHA PBT'!D:D,0)),TRUE,FALSE) -> FALSE | AD10: {=IF(ISNUMBER(MATCH(F10, _xlfn._xlws.FILTER('ECHA biocidal AS'!C:C, 'ECHA biocidal AS'!H:H="true"), 0)), "yes", FALSE)} -> FALSE | AE10: =IF(AND(AD10=FALSE,(ISNUMBER(MATCH(F10,'ECHA biocidal AS'!C:C,0)))),TRUE,FALSE) -> TRUE | AF10: {=IF(ISNUMBER(MATCH(F10, _xlfn._xlws.FILTER('ECHA biocidal AS'!C:C, 'ECHA biocidal AS'!M:M="Approved"), 0)), TRUE, FALSE)} -> FALSE | AH10: =IF(ISNUMBER(MATCH(F10,'EQS WFD'!D:D,0)),TRUE,FALSE) -> FALSE | AJ10: =IF(ISNUMBER(MATCH(F10,'SoC_Ctgb 20181010'!C:C,0)),TRUE,FALSE) -> FALSE
F11: 7664-93-9 | L11: 80 | M11: =IF(COUNTIF(N11:W11,TRUE)>0,TRUE,"Not Found") -> Not Found | N11: =IF(AND((COUNTIF($E$4,"*H3*")),(COUNTIF(K11,"*H3*"))),TRUE,FALSE) -> FALSE | P11: =AD11 -> FALSE | Q11: =AE11 -> FALSE | R11: =AF11 -> FALSE | T11: =AC11 -> FALSE | U11: =AD11 -> FALSE | W11: {=IF(ISBLANK(F11),"FALSE",IFERROR((VLOOKUP(TRIM(F11),TRIM(SCOEL!$B$12:$E$400),3,"FALSE")),"FALSE"))} -> 105 | X11: =IF(COUNTIF(Z11:AI11,TRUE)>0,TRUE,"Not Found") -> Not Found | Y11: =IF(AND((COUNTIF($E$4,"*H4*")),(COUNTIF(K11,"*H4*"))),TRUE,FALSE) -> FALSE | Z11: =IF(COUNTIF(K11,"*H410*"),IF(J11*L11>25,"Cat. 1","not classified"),IF(COUNTIF(K11,"*H411*"),IF(L11>=25,"Cat. 2","not classified"),"geen H411")) -> geen H411 | AA11: =IF(ISNUMBER(MATCH(F11,'ECHA POP'!D:D,0)),TRUE,FALSE) -> FALSE | AB11: =IF(ISNUMBER(MATCH(F11,'ECHA candidate SVHC'!D:D,0)),TRUE,FALSE) -> FALSE | AC11: =IF(ISNUMBER(MATCH(F11,'ECHA PBT'!D:D,0)),TRUE,FALSE) -> FALSE | AD11: {=IF(ISNUMBER(MATCH(F11, _xlfn._xlws.FILTER('ECHA biocidal AS'!C:C, 'ECHA biocidal AS'!H:H="true"), 0)), "yes", FALSE)} -> FALSE | AE11: =IF(AND(AD11=FALSE,(ISNUMBER(MATCH(F11,'ECHA biocidal AS'!C:C,0)))),TRUE,FALSE) -> FALSE | AF11: {=IF(ISNUMBER(MATCH(F11, _xlfn._xlws.FILTER('ECHA biocidal AS'!C:C, 'ECHA biocidal AS'!M:M="Approved"), 0)), TRUE, FALSE)} -> FALSE | AH11: =IF(ISNUMBER(MATCH(F11,'EQS WFD'!D:D,0)),TRUE,FALSE) -> FALSE | AJ11: =IF(ISNUMBER(MATCH(F11,'SoC_Ctgb 20181010'!C:C,0)),TRUE,FALSE) -> FALSE
F12: 107-13-1 | L12: 5 | M12: =IF(COUNTIF(N12:W12,TRUE)>0,TRUE,"Not Found") -> Not Found | N12: =IF(AND((COUNTIF($E$4,"*H3*")),(COUNTIF(K12,"*H3*"))),TRUE,FALSE) -> FALSE | P12: =AD12 -> FALSE | Q12: =AE12 -> FALSE | R12: =AF12 -> FALSE | T12: =AC12 -> FALSE | U12: =AD12 -> FALSE | W12: {=IF(ISBLANK(F12),"FALSE",IFERROR((VLOOKUP(TRIM(F12),TRIM(SCOEL!$B$12:$E$400),3,"FALSE")),"FALSE"))} -> 104 | X12: =IF(COUNTIF(Z12:AI12,TRUE)>0,TRUE,"Not Found") -> Not Found | Y12: =IF(AND((COUNTIF($E$4,"*H4*")),(COUNTIF(K12,"*H4*"))),TRUE,FALSE) -> FALSE | Z12: =IF(COUNTIF(K12,"*H410*"),IF(J12*L12>25,"Cat. 1","not classified"),IF(COUNTIF(K12,"*H411*"),IF(L12>=25,"Cat. 2","not classified"),"geen H411")) -> geen H411 | AA12: =IF(ISNUMBER(MATCH(F12,'ECHA POP'!D:D,0)),TRUE,FALSE) -> FALSE | AB12: =IF(ISNUMBER(MATCH(F12,'ECHA candidate SVHC'!D:D,0)),TRUE,FALSE) -> FALSE | AC12: =IF(ISNUMBER(MATCH(F12,'ECHA PBT'!D:D,0)),TRUE,FALSE) -> FALSE | AD12: {=IF(ISNUMBER(MATCH(F12, _xlfn._xlws.FILTER('ECHA biocidal AS'!C:C, 'ECHA biocidal AS'!H:H="true"), 0)), "yes", FALSE)} -> FALSE | AE12: =IF(AND(AD12=FALSE,(ISNUMBER(MATCH(F12,'ECHA biocidal AS'!C:C,0)))),TRUE,FALSE) -> FALSE | AF12: {=IF(ISNUMBER(MATCH(F12, _xlfn._xlws.FILTER('ECHA biocidal AS'!C:C, 'ECHA biocidal AS'!M:M="Approved"), 0)), TRUE, FALSE)} -> FALSE | AH12: =IF(ISNUMBER(MATCH(F12,'EQS WFD'!D:D,0)),TRUE,FALSE) -> FALSE | AJ12: =IF(ISNUMBER(MATCH(F12,'SoC_Ctgb 20181010'!C:C,0)),TRUE,FALSE) -> FALSE
M13: =IF(COUNTIF(N13:W13,TRUE)>0,TRUE,"Not Found") -> Not Found | N13: =IF(AND((COUNTIF($E$4,"*H3*")),(COUNTIF(K13,"*H3*"))),TRUE,FALSE) -> FALSE | P13: =AD13 -> FALSE | Q13: =AE13 -> FALSE | R13: =AF13 -> FALSE | T13: =AC13 -> FALSE | U13: =AD13 -> FALSE | W13: {=IF(ISBLANK(F13),"FALSE",IFERROR((VLOOKUP(TRIM(F13),TRIM(SCOEL!$B$12:$E$400),3,"FALSE")),"FALSE"))} -> FALSE | X13: =IF(COUNTIF(Z13:AI13,TRUE)>0,TRUE,"Not Found") -> Not Found | Y13: =IF(AND((COUNTIF($E$4,"*H4*")),(COUNTIF(K13,"*H4*"))),TRUE,FALSE) -> FALSE | Z13: =IF(COUNTIF(K13,"*H410*"),IF(J13*L13>25,"Cat. 1","not classified"),IF(COUNTIF(K13,"*H411*"),IF(L13>=25,"Cat. 2","not classified"),"geen H411")) -> geen H411 | AA13: =IF(ISNUMBER(MATCH(F13,'ECHA POP'!D:D,0)),TRUE,FALSE) -> FALSE | AB13: =IF(ISNUMBER(MATCH(F13,'ECHA candidate SVHC'!D:D,0)),TRUE,FALSE) -> FALSE | AC13: =IF(ISNUMBER(MATCH(F13,'ECHA PBT'!D:D,0)),TRUE,FALSE) -> FALSE | AD13: {=IF(ISNUMBER(MATCH(F13, _xlfn._xlws.FILTER('ECHA biocidal AS'!C:C, 'ECHA biocidal AS'!H:H="true"), 0)), "yes", FALSE)} -> FALSE | AE13: =IF(AND(AD13=FALSE,(ISNUMBER(MATCH(F13,'ECHA biocidal AS'!C:C,0)))),TRUE,FALSE) -> FALSE | AF13: {=IF(ISNUMBER(MATCH(F13, _xlfn._xlws.FILTER('ECHA biocidal AS'!C:C, 'ECHA biocidal AS'!M:M="Approved"), 0)), TRUE, FALSE)} -> FALSE | AH13: =IF(ISNUMBER(MATCH(F13,'EQS WFD'!D:D,0)),TRUE,FALSE) -> FALSE | AJ13: =IF(ISNUMBER(MATCH(F13,'SoC_Ctgb 20181010'!C:C,0)),TRUE,FALSE) -> FALSE
M14: =IF(COUNTIF(N14:W14,TRUE)>0,TRUE,"Not Found") -> Not Found | N14: =IF(AND((COUNTIF($E$4,"*H3*")),(COUNTIF(K14,"*H3*"))),TRUE,FALSE) -> FALSE | P14: =AD14 -> FALSE | Q14: =AE14 -> FALSE | R14: =AF14 -> FALSE | T14: =AC14 -> FALSE | U14: =AD14 -> FALSE | W14: {=IF(ISBLANK(F14),"FALSE",IFERROR((VLOOKUP(TRIM(F14),TRIM(SCOEL!$B$12:$E$400),3,"FALSE")),"FALSE"))} -> FALSE | X14: =IF(COUNTIF(Z14:AI14,TRUE)>0,TRUE,"Not Found") -> Not Found | Y14: =IF(AND((COUNTIF($E$4,"*H4*")),(COUNTIF(K14,"*H4*"))),TRUE,FALSE) -> FALSE | Z14: =IF(COUNTIF(K14,"*H410*"),IF(J14*L14>25,"Cat. 1",IF(J14*L14*10>25,"Cat. 2","not classified")),IF(COUNTIF(K14,"*H411*"),IF(L14>=25,"Cat. 2","not classified"),"geen H411")) -> geen H411 | AA14: =IF(ISNUMBER(MATCH(F14,'ECHA POP'!D:D,0)),TRUE,FALSE) -> FALSE | AB14: =IF(ISNUMBER(MATCH(F14,'ECHA candidate SVHC'!D:D,0)),TRUE,FALSE) -> FALSE | AC14: =IF(ISNUMBER(MATCH(F14,'ECHA PBT'!D:D,0)),TRUE,FALSE) -> FALSE | AD14: {=IF(ISNUMBER(MATCH(F14, _xlfn._xlws.FILTER('ECHA biocidal AS'!C:C, 'ECHA biocidal AS'!H:H="true"), 0)), "yes", FALSE)} -> FALSE | AE14: =IF(AND(AD14=FALSE,(ISNUMBER(MATCH(F14,'ECHA biocidal AS'!C:C,0)))),TRUE,FALSE) -> FALSE | AF14: {=IF(ISNUMBER(MATCH(F14, _xlfn._xlws.FILTER('ECHA biocidal AS'!C:C, 'ECHA biocidal AS'!M:M="Approved"), 0)), TRUE, FALSE)} -> FALSE | AH14: =IF(ISNUMBER(MATCH(F14,'EQS WFD'!D:D,0)),TRUE,FALSE) -> FALSE | AJ14: =IF(ISNUMBER(MATCH(F14,'SoC_Ctgb 20181010'!C:C,0)),TRUE,FALSE) -> FALSE
M15: =IF(COUNTIF(N15:W15,TRUE)>0,TRUE,"Not Found") -> Not Found | N15: =IF(AND((COUNTIF($E$4,"*H3*")),(COUNTIF(K15,"*H3*"))),TRUE,FALSE) -> FALSE | P15: =AD15 -> FALSE | Q15: =AE15 -> FALSE | R15: =AF15 -> FALSE | T15: =AC15 -> FALSE | U15: =AD15 -> FALSE | W15: {=IF(ISBLANK(F15),"FALSE",IFERROR((VLOOKUP(TRIM(F15),TRIM(SCOEL!$B$12:$E$400),3,"FALSE")),"FALSE"))} -> FALSE | X15: =IF(COUNTIF(Z15:AI15,TRUE)>0,TRUE,"Not Found") -> Not Found | Y15: =IF(AND((COUNTIF($E$4,"*H4*")),(COUNTIF(K15,"*H4*"))),TRUE,FALSE) -> FALSE | Z15: =IF(COUNTIF(K15,"*H410*"),IF(J15*L15>25,"Cat. 1","not classified"),IF(COUNTIF(K15,"*H411*"),IF(L15>=25,"Cat. 2","not classified"),"geen H411")) -> geen H411 | AA15: =IF(ISNUMBER(MATCH(F15,'ECHA POP'!D:D,0)),TRUE,FALSE) -> FALSE | AB15: =IF(ISNUMBER(MATCH(F15,'ECHA candidate SVHC'!D:D,0)),TRUE,FALSE) -> FALSE | AC15: =IF(ISNUMBER(MATCH(F15,'ECHA PBT'!D:D,0)),TRUE,FALSE) -> FALSE | AD15: {=IF(ISNUMBER(MATCH(F15, _xlfn._xlws.FILTER('ECHA biocidal AS'!C:C, 'ECHA biocidal AS'!H:H="true"), 0)), "yes", FALSE)} -> FALSE | AE15: =IF(AND(AD15=FALSE,(ISNUMBER(MATCH(F15,'ECHA biocidal AS'!C:C,0)))),TRUE,FALSE) -> FALSE | AF15: {=IF(ISNUMBER(MATCH(F15, _xlfn._xlws.FILTER('ECHA biocidal AS'!C:C, 'ECHA biocidal AS'!M:M="Approved"), 0)), TRUE, FALSE)} -> FALSE | AH15: =IF(ISNUMBER(MATCH(F15,'EQS WFD'!D:D,0)),TRUE,FALSE) -> FALSE | AJ15: =IF(ISNUMBER(MATCH(F15,'SoC_Ctgb 20181010'!C:C,0)),TRUE,FALSE) -> FALSE
M16: =IF(COUNTIF(N16:W16,TRUE)>0,TRUE,"Not Found") -> Not Found | N16: =IF(AND((COUNTIF($E$4,"*H3*")),(COUNTIF(K16,"*H3*"))),TRUE,FALSE) -> FALSE | P16: =AD16 -> FALSE | Q16: =AE16 -> FALSE | R16: =AF16 -> FALSE | T16: =AC16 -> FALSE | U16: =AD16 -> FALSE | W16: {=IF(ISBLANK(F16),"FALSE",IFERROR((VLOOKUP(TRIM(F16),TRIM(SCOEL!$B$12:$E$400),3,"FALSE")),"FALSE"))} -> FALSE | X16: =IF(COUNTIF(Z16:AI16,TRUE)>0,TRUE,"Not Found") -> Not Found | Y16: =IF(AND((COUNTIF($E$4,"*H4*")),(COUNTIF(K16,"*H4*"))),TRUE,FALSE) -> FALSE | Z16: =IF(COUNTIF(K16,"*H410*"),IF(J16*L16>25,"Cat. 1","not classified"),IF(COUNTIF(K16,"*H411*"),IF(L16>=25,"Cat. 2","not classified"),IF(COUNTIF(K15,"*H412*"),IF(L15>=25,"Cat. 3","not classified")))) -> FALSE | AA16: =IF(ISNUMBER(MATCH(F16,'ECHA POP'!D:D,0)),TRUE,FALSE) -> FALSE | AB16: =IF(ISNUMBER(MATCH(F16,'ECHA candidate SVHC'!D:D,0)),TRUE,FALSE) -> FALSE | AC16: =IF(ISNUMBER(MATCH(F16,'ECHA PBT'!D:D,0)),TRUE,FALSE) -> FALSE | AD16: {=IF(ISNUMBER(MATCH(F16, _xlfn._xlws.FILTER('ECHA biocidal AS'!C:C, 'ECHA biocidal AS'!H:H="true"), 0)), "yes", FALSE)} -> FALSE | AE16: =IF(AND(AD16=FALSE,(ISNUMBER(MATCH(F16,'ECHA biocidal AS'!C:C,0)))),TRUE,FALSE) -> FALSE | AF16: {=IF(ISNUMBER(MATCH(F16, _xlfn._xlws.FILTER('ECHA biocidal AS'!C:C, 'ECHA biocidal AS'!M:M="Approved"), 0)), TRUE, FALSE)} -> FALSE | AH16: =IF(ISNUMBER(MATCH(F16,'EQS WFD'!D:D,0)),TRUE,FALSE) -> FALSE | AJ16: =IF(ISNUMBER(MATCH(F16,'SoC_Ctgb 20181010'!C:C,0)),TRUE,FALSE) -> FALSE
M17: =IF(COUNTIF(N17:W17,TRUE)>0,TRUE,"Not Found") -> Not Found | N17: =IF(AND((COUNTIF($E$4,"*H3*")),(COUNTIF(K17,"*H3*"))),TRUE,FALSE) -> FALSE | P17: =AD17 -> FALSE | Q17: =AE17 -> FALSE | R17: =AF17 -> FALSE | T17: =AC17 -> FALSE | U17: =AD17 -> FALSE | W17: {=IF(ISBLANK(F17),"FALSE",IFERROR((VLOOKUP(TRIM(F17),TRIM(SCOEL!$B$12:$E$400),3,"FALSE")),"FALSE"))} -> FALSE | X17: =IF(COUNTIF(Z17:AI17,TRUE)>0,TRUE,"Not Found") -> Not Found | Y17: =IF(AND((COUNTIF($E$4,"*H4*")),(COUNTIF(K17,"*H4*"))),TRUE,FALSE) -> FALSE | Z17: =IF(COUNTIF(K17,"*H410*"),IF(J17*L17>25,"Cat. 1","not classified"),IF(COUNTIF(K17,"*H411*"),IF(L17>=25,"Cat. 2","not classified"),"geen H411")) -> geen H411 | AA17: =IF(ISNUMBER(MATCH(F17,'ECHA POP'!D:D,0)),TRUE,FALSE) -> FALSE | AB17: =IF(ISNUMBER(MATCH(F17,'ECHA candidate SVHC'!D:D,0)),TRUE,FALSE) -> FALSE | AC17: =IF(ISNUMBER(MATCH(F17,'ECHA PBT'!D:D,0)),TRUE,FALSE) -> FALSE | AD17: {=IF(ISNUMBER(MATCH(F17, _xlfn._xlws.FILTER('ECHA biocidal AS'!C:C, 'ECHA biocidal AS'!H:H="true"), 0)), "yes", FALSE)} -> FALSE | AE17: =IF(AND(AD17=FALSE,(ISNUMBER(MATCH(F17,'ECHA biocidal AS'!C:C,0)))),TRUE,FALSE) -> FALSE | AF17: {=IF(ISNUMBER(MATCH(F17, _xlfn._xlws.FILTER('ECHA biocidal AS'!C:C, 'ECHA biocidal AS'!M:M="Approved"), 0)), TRUE, FALSE)} -> FALSE | AH17: =IF(ISNUMBER(MATCH(F17,'EQS WFD'!D:D,0)),TRUE,FALSE) -> FALSE | AJ17: =IF(ISNUMBER(MATCH(F17,'SoC_Ctgb 20181010'!C:C,0)),TRUE,FALSE) -> FALSE
M18: =IF(COUNTIF(N18:W18,TRUE)>0,TRUE,"Not Found") -> Not Found | N18: =IF(AND((COUNTIF($E$4,"*H3*")),(COUNTIF(K18,"*H3*"))),TRUE,FALSE) -> FALSE | P18: =AD18 -> FALSE | Q18: =AE18 -> FALSE | R18: =AF18 -> FALSE | T18: =AC18 -> FALSE | U18: =AD18 -> FALSE | W18: {=IF(ISBLANK(F18),"FALSE",IFERROR((VLOOKUP(TRIM(F18),TRIM(SCOEL!$B$12:$E$400),3,"FALSE")),"FALSE"))} -> FALSE | X18: =IF(COUNTIF(Z18:AI18,TRUE)>0,TRUE,"Not Found") -> Not Found | Y18: =IF(AND((COUNTIF($E$4,"*H4*")),(COUNTIF(K18,"*H4*"))),TRUE,FALSE) -> FALSE | Z18: =IF(COUNTIF(K18,"*H410*"),IF(J18*L18>25,"Cat. 1","not classified"),IF(COUNTIF(K18,"*H411*"),IF(L18>=25,"Cat. 2","not classified"),"geen H411")) -> geen H411 | AA18: =IF(ISNUMBER(MATCH(F18,'ECHA POP'!D:D,0)),TRUE,FALSE) -> FALSE | AB18: =IF(ISNUMBER(MATCH(F18,'ECHA candidate SVHC'!D:D,0)),TRUE,FALSE) -> FALSE | AC18: =IF(ISNUMBER(MATCH(F18,'ECHA PBT'!D:D,0)),TRUE,FALSE) -> FALSE | AD18: {=IF(ISNUMBER(MATCH(F18, _xlfn._xlws.FILTER('ECHA biocidal AS'!C:C, 'ECHA biocidal AS'!H:H="true"), 0)), "yes", FALSE)} -> FALSE | AE18: =IF(AND(AD18=FALSE,(ISNUMBER(MATCH(F18,'ECHA biocidal AS'!C:C,0)))),TRUE,FALSE) -> FALSE | AF18: {=IF(ISNUMBER(MATCH(F18, _xlfn._xlws.FILTER('ECHA biocidal AS'!C:C, 'ECHA biocidal AS'!M:M="Approved"), 0)), TRUE, FALSE)} -> FALSE | AH18: =IF(ISNUMBER(MATCH(F18,'EQS WFD'!D:D,0)),TRUE,FALSE) -> FALSE | AJ18: =IF(ISNUMBER(MATCH(F18,'SoC_Ctgb 20181010'!C:C,0)),TRUE,FALSE) -> FALSE
M19: =IF(COUNTIF(N19:W19,TRUE)>0,TRUE,"Not Found") -> Not Found | N19: =IF(AND((COUNTIF($E$4,"*H3*")),(COUNTIF(K19,"*H3*"))),TRUE,FALSE) -> FALSE | P19: =AD19 -> FALSE | Q19: =AE19 -> FALSE | R19: =AF19 -> FALSE | T19: =AC19 -> FALSE | U19: =AD19 -> FALSE | W19: {=IF(ISBLANK(F19),"FALSE",IFERROR((VLOOKUP(TRIM(F19),TRIM(SCOEL!$B$12:$E$400),3,"FALSE")),"FALSE"))} -> FALSE | X19: =IF(COUNTIF(Z19:AI19,TRUE)>0,TRUE,"Not Found") -> Not Found | Y19: =IF(AND((COUNTIF($E$4,"*H4*")),(COUNTIF(K19,"*H4*"))),TRUE,FALSE) -> FALSE | Z19: =IF(COUNTIF(K19,"*H410*"),IF(J19*L19>25,"Cat. 1","not classified"),IF(COUNTIF(K19,"*H411*"),IF(L19>=25,"Cat. 2","not classified"),"geen H411")) -> geen H411 | AA19: =IF(ISNUMBER(MATCH(F19,'ECHA POP'!D:D,0)),TRUE,FALSE) -> FALSE | AB19: =IF(ISNUMBER(MATCH(F19,'ECHA candidate SVHC'!D:D,0)),TRUE,FALSE) -> FALSE | AC19: =IF(ISNUMBER(MATCH(F19,'ECHA PBT'!D:D,0)),TRUE,FALSE) -> FALSE | AD19: {=IF(ISNUMBER(MATCH(F19, _xlfn._xlws.FILTER('ECHA biocidal AS'!C:C, 'ECHA biocidal AS'!H:H="true"), 0)), "yes", FALSE)} -> FALSE | AE19: =IF(AND(AD19=FALSE,(ISNUMBER(MATCH(F19,'ECHA biocidal AS'!C:C,0)))),TRUE,FALSE) -> FALSE | AF19: {=IF(ISNUMBER(MATCH(F19, _xlfn._xlws.FILTER('ECHA biocidal AS'!C:C, 'ECHA biocidal AS'!M:M="Approved"), 0)), TRUE, FALSE)} -> FALSE | AH19: =IF(ISNUMBER(MATCH(F19,'EQS WFD'!D:D,0)),TRUE,FALSE) -> FALSE | AJ19: =IF(ISNUMBER(MATCH(F19,'SoC_Ctgb 20181010'!C:C,0)),TRUE,FALSE) -> FALSE
B20: BP2 | M20: =IF(COUNTIF(N20:W20,TRUE)>0,TRUE,"Not Found") -> Not Found | N20: =IF(AND((COUNTIF($E$4,"*H3*")),(COUNTIF(K20,"*H3*"))),TRUE,FALSE) -> FALSE | P20: =AD20 -> FALSE | Q20: =AE20 -> FALSE | R20: =AF20 -> FALSE | T20: =AC20 -> FALSE | U20: =AD20 -> FALSE | W20: {=IF(ISBLANK(F20),"FALSE",IFERROR((VLOOKUP(TRIM(F20),TRIM(SCOEL!$B$12:$E$400),3,"FALSE")),"FALSE"))} -> FALSE | X20: =IF(COUNTIF(Z20:AI20,TRUE)>0,TRUE,"Not Found") -> Not Found | Y20: =IF(AND((COUNTIF($E$4,"*H4*")),(COUNTIF(K20,"*H4*"))),TRUE,FALSE) -> FALSE | Z20: =IF(COUNTIF(K20,"*H410*"),IF(J20*L20>25,"Cat. 1","not classified"),IF(COUNTIF(K20,"*H411*"),IF(L20>=25,"Cat. 2","not classified"),"geen H411")) -> geen H411 | AA20: =IF(ISNUMBER(MATCH(F20,'ECHA POP'!D:D,0)),TRUE,FALSE) -> FALSE | AB20: =IF(ISNUMBER(MATCH(F20,'ECHA candidate SVHC'!D:D,0)),TRUE,FALSE) -> FALSE | AC20: =IF(ISNUMBER(MATCH(F20,'ECHA PBT'!D:D,0)),TRUE,FALSE) -> FALSE | AD20: {=IF(ISNUMBER(MATCH(F20, _xlfn._xlws.FILTER('ECHA biocidal AS'!C:C, 'ECHA biocidal AS'!H:H="true"), 0)), "yes", FALSE)} -> FALSE | AE20: =IF(AND(AD20=FALSE,(ISNUMBER(MATCH(F20,'ECHA biocidal AS'!C:C,0)))),TRUE,FALSE) -> FALSE | AF20: {=IF(ISNUMBER(MATCH(F20, _xlfn._xlws.FILTER('ECHA biocidal AS'!C:C, 'ECHA biocidal AS'!M:M="Approved"), 0)), TRUE, FALSE)} -> FALSE | AH20: =IF(ISNUMBER(MATCH(F20,'EQS WFD'!D:D,0)),TRUE,FALSE) -> FALSE | AJ20: =IF(ISNUMBER(MATCH(F20,'SoC_Ctgb 20181010'!C:C,0)),TRUE,FALSE) -> FALSE
M21: =IF(COUNTIF(N21:W21,TRUE)>0,TRUE,"Not Found") -> Not Found | N21: =IF(AND((COUNTIF($E$4,"*H3*")),(COUNTIF(K21,"*H3*"))),TRUE,FALSE) -> FALSE | P21: =AD21 -> FALSE | Q21: =AE21 -> FALSE | R21: =AF21 -> FALSE | T21: =AC21 -> FALSE | U21: =AD21 -> FALSE | W21: {=IF(ISBLANK(F21),"FALSE",IFERROR((VLOOKUP(TRIM(F21),TRIM(SCOEL!$B$12:$E$400),3,"FALSE")),"FALSE"))} -> FALSE | X21: =IF(COUNTIF(Z21:AI21,TRUE)>0,TRUE,"Not Found") -> Not Found | Y21: =IF(AND((COUNTIF($E$4,"*H4*")),(COUNTIF(K21,"*H4*"))),TRUE,FALSE) -> FALSE | Z21: =IF(COUNTIF(K21,"*H410*"),IF(J21*L21>25,"Cat. 1","not classified"),IF(COUNTIF(K21,"*H411*"),IF(L21>=25,"Cat. 2","not classified"),"geen H411")) -> geen H411 | AA21: =IF(ISNUMBER(MATCH(F21,'ECHA POP'!D:D,0)),TRUE,FALSE) -> FALSE | AB21: =IF(ISNUMBER(MATCH(F21,'ECHA candidate SVHC'!D:D,0)),TRUE,FALSE) -> FALSE | AC21: =IF(ISNUMBER(MATCH(F21,'ECHA PBT'!D:D,0)),TRUE,FALSE) -> FALSE | AD21: {=IF(ISNUMBER(MATCH(F21, _xlfn._xlws.FILTER('ECHA biocidal AS'!C:C, 'ECHA biocidal AS'!H:H="true"), 0)), "yes", FALSE)} -> FALSE | AE21: =IF(AND(AD21=FALSE,(ISNUMBER(MATCH(F21,'ECHA biocidal AS'!C:C,0)))),TRUE,FALSE) -> FALSE | AF21: {=IF(ISNUMBER(MATCH(F21, _xlfn._xlws.FILTER('ECHA biocidal AS'!C:C, 'ECHA biocidal AS'!M:M="Approved"), 0)), TRUE, FALSE)} -> FALSE | AH21: =IF(ISNUMBER(MATCH(F21,'EQS WFD'!D:D,0)),TRUE,FALSE) -> FALSE | AJ21: =IF(ISNUMBER(MATCH(F21,'SoC_Ctgb 20181010'!C:C,0)),TRUE,FALSE) -> FALSE
M22: =IF(COUNTIF(N22:W22,TRUE)>0,TRUE,"Not Found") -> Not Found | N22: =IF(AND((COUNTIF($E$4,"*H3*")),(COUNTIF(K22,"*H3*"))),TRUE,FALSE) -> FALSE | P22: =AD22 -> FALSE | Q22: =AE22 -> FALSE | R22: =AF22 -> FALSE | T22: =AC22 -> FALSE | U22: =AD22 -> FALSE | W22: {=IF(ISBLANK(F22),"FALSE",IFERROR((VLOOKUP(TRIM(F22),TRIM(SCOEL!$B$12:$E$400),3,"FALSE")),"FALSE"))} -> FALSE | X22: =IF(COUNTIF(Z22:AI22,TRUE)>0,TRUE,"Not Found") -> Not Found | Y22: =IF(AND((COUNTIF($E$4,"*H4*")),(COUNTIF(K22,"*H4*"))),TRUE,FALSE) -> FALSE | Z22: =IF(COUNTIF(K22,"*H410*"),IF(J22*L22>25,"Cat. 1","not classified"),IF(COUNTIF(K22,"*H411*"),IF(L22>=25,"Cat. 2","not classified"),"geen H411")) -> geen H411 | AA22: =IF(ISNUMBER(MATCH(F22,'ECHA POP'!D:D,0)),TRUE,FALSE) -> FALSE | AB22: =IF(ISNUMBER(MATCH(F22,'ECHA candidate SVHC'!D:D,0)),TRUE,FALSE) -> FALSE | AC22: =IF(ISNUMBER(MATCH(F22,'ECHA PBT'!D:D,0)),TRUE,FALSE) -> FALSE | AD22: {=IF(ISNUMBER(MATCH(F22, _xlfn._xlws.FILTER('ECHA biocidal AS'!C:C, 'ECHA biocidal AS'!H:H="true"), 0)), "yes", FALSE)} -> FALSE | AE22: =IF(AND(AD22=FALSE,(ISNUMBER(MATCH(F22,'ECHA biocidal AS'!C:C,0)))),TRUE,FALSE) -> FALSE | AF22: {=IF(ISNUMBER(MATCH(F22, _xlfn._xlws.FILTER('ECHA biocidal AS'!C:C, 'ECHA biocidal AS'!M:M="Approved"), 0)), TRUE, FALSE)} -> FALSE | AH22: =IF(ISNUMBER(MATCH(F22,'EQS WFD'!D:D,0)),TRUE,FALSE) -> FALSE | AJ22: =IF(ISNUMBER(MATCH(F22,'SoC_Ctgb 20181010'!C:C,0)),TRUE,FALSE) -> FALSE
M23: =IF(COUNTIF(N23:W23,TRUE)>0,TRUE,"Not Found") -> Not Found | N23: =IF(AND((COUNTIF($E$4,"*H3*")),(COUNTIF(K23,"*H3*"))),TRUE,FALSE) -> FALSE | P23: =AD23 -> FALSE | Q23: =AE23 -> FALSE | R23: =AF23 -> FALSE | T23: =AC23 -> FALSE | U23: =AD23 -> FALSE | W23: {=IF(ISBLANK(F23),"FALSE",IFERROR((VLOOKUP(TRIM(F23),TRIM(SCOEL!$B$12:$E$400),3,"FALSE")),"FALSE"))} -> FALSE | X23: =IF(COUNTIF(Z23:AI23,TRUE)>0,TRUE,"Not Found") -> Not Found | Y23: =IF(AND((COUNTIF($E$4,"*H4*")),(COUNTIF(K23,"*H4*"))),TRUE,FALSE) -> FALSE | Z23: =IF(COUNTIF(K23,"*H410*"),IF(J23*L23>25,"Cat. 1","not classified"),IF(COUNTIF(K23,"*H411*"),IF(L23>=25,"Cat. 2","not classified"),"geen H411")) -> geen H411 | AA23: =IF(ISNUMBER(MATCH(F23,'ECHA POP'!D:D,0)),TRUE,FALSE) -> FALSE | AB23: =IF(ISNUMBER(MATCH(F23,'ECHA candidate SVHC'!D:D,0)),TRUE,FALSE) -> FALSE | AC23: =IF(ISNUMBER(MATCH(F23,'ECHA PBT'!D:D,0)),TRUE,FALSE) -> FALSE | AD23: {=IF(ISNUMBER(MATCH(F23, _xlfn._xlws.FILTER('ECHA biocidal AS'!C:C, 'ECHA biocidal AS'!H:H="true"), 0)), "yes", FALSE)} -> FALSE | AE23: =IF(AND(AD23=FALSE,(ISNUMBER(MATCH(F23,'ECHA biocidal AS'!C:C,0)))),TRUE,FALSE) -> FALSE | AF23: {=IF(ISNUMBER(MATCH(F23, _xlfn._xlws.FILTER('ECHA biocidal AS'!C:C, 'ECHA biocidal AS'!M:M="Approved"), 0)), TRUE, FALSE)} -> FALSE | AH23: =IF(ISNUMBER(MATCH(F23,'EQS WFD'!D:D,0)),TRUE,FALSE) -> FALSE | AJ23: =IF(ISNUMBER(MATCH(F23,'SoC_Ctgb 20181010'!C:C,0)),TRUE,FALSE) -> FALSE
M24: =IF(COUNTIF(N24:W24,TRUE)>0,TRUE,"Not Found") -> Not Found | N24: =IF(AND((COUNTIF($E$4,"*H3*")),(COUNTIF(K24,"*H3*"))),TRUE,FALSE) -> FALSE | P24: =AD24 -> FALSE | Q24: =AE24 -> FALSE | R24: =AF24 -> FALSE | T24: =AC24 -> FALSE | U24: =AD24 -> FALSE | W24: {=IF(ISBLANK(F24),"FALSE",IFERROR((VLOOKUP(TRIM(F24),TRIM(SCOEL!$B$12:$E$400),3,"FALSE")),"FALSE"))} -> FALSE | X24: =IF(COUNTIF(Z24:AI24,TRUE)>0,TRUE,"Not Found") -> Not Found | Y24: =IF(AND((COUNTIF($E$4,"*H4*")),(COUNTIF(K24,"*H4*"))),TRUE,FALSE) -> FALSE | Z24: =IF(COUNTIF(K24,"*H410*"),IF(J24*L24>25,"Cat. 1","not classified"),IF(COUNTIF(K24,"*H411*"),IF(L24>=25,"Cat. 2","not classified"),"geen H411")) -> geen H411 | AA24: =IF(ISNUMBER(MATCH(F24,'ECHA POP'!D:D,0)),TRUE,FALSE) -> FALSE | AB24: =IF(ISNUMBER(MATCH(F24,'ECHA candidate SVHC'!D:D,0)),TRUE,FALSE) -> FALSE | AC24: =IF(ISNUMBER(MATCH(F24,'ECHA PBT'!D:D,0)),TRUE,FALSE) -> FALSE | AD24: {=IF(ISNUMBER(MATCH(F24, _xlfn._xlws.FILTER('ECHA biocidal AS'!C:C, 'ECHA biocidal AS'!H:H="true"), 0)), "yes", FALSE)} -> FALSE | AE24: =IF(AND(AD24=FALSE,(ISNUMBER(MATCH(F24,'ECHA biocidal AS'!C:C,0)))),TRUE,FALSE) -> FALSE | AF24: {=IF(ISNUMBER(MATCH(F24, _xlfn._xlws.FILTER('ECHA biocidal AS'!C:C, 'ECHA biocidal AS'!M:M="Approved"), 0)), TRUE, FALSE)} -> FALSE | AH24: =IF(ISNUMBER(MATCH(F24,'EQS WFD'!D:D,0)),TRUE,FALSE) -> FALSE
M25: =IF(COUNTIF(N25:W25,TRUE)>0,TRUE,"Not Found") -> Not Found | N25: =IF(AND((COUNTIF($E$4,"*H3*")),(COUNTIF(K25,"*H3*"))),TRUE,FALSE) -> FALSE | P25: =AD25 -> FALSE | Q25: =AE25 -> FALSE | R25: =AF25 -> FALSE | T25: =AC25 -> FALSE | U25: =AD25 -> FALSE | W25: {=IF(ISBLANK(F25),"FALSE",IFERROR((VLOOKUP(TRIM(F25),TRIM(SCOEL!$B$12:$E$400),3,"FALSE")),"FALSE"))} -> FALSE | X25: =IF(COUNTIF(Z25:AI25,TRUE)>0,TRUE,"Not Found") -> Not Found | Y25: =IF(AND((COUNTIF($E$4,"*H4*")),(COUNTIF(K25,"*H4*"))),TRUE,FALSE) -> FALSE | Z25: =IF(COUNTIF(K25,"*H410*"),IF(J25*L25>25,"Cat. 1","not classified"),IF(COUNTIF(K25,"*H411*"),IF(L25>=25,"Cat. 2","not classified"),"geen H411")) -> geen H411 | AA25: =IF(ISNUMBER(MATCH(F25,'ECHA POP'!D:D,0)),TRUE,FALSE) -> FALSE | AB25: =IF(ISNUMBER(MATCH(F25,'ECHA candidate SVHC'!D:D,0)),TRUE,FALSE) -> FALSE | AC25: =IF(ISNUMBER(MATCH(F25,'ECHA PBT'!D:D,0)),TRUE,FALSE) -> FALSE | AD25: {=IF(ISNUMBER(MATCH(F25, _xlfn._xlws.FILTER('ECHA biocidal AS'!C:C, 'ECHA biocidal AS'!H:H="true"), 0)), "yes", FALSE)} -> FALSE | AE25: =IF(AND(AD25=FALSE,(ISNUMBER(MATCH(F25,'ECHA biocidal AS'!C:C,0)))),TRUE,FALSE) -> FALSE | AF25: {=IF(ISNUMBER(MATCH(F25, _xlfn._xlws.FILTER('ECHA biocidal AS'!C:C, 'ECHA biocidal AS'!M:M="Approved"), 0)), TRUE, FALSE)} -> FALSE | AH25: =IF(ISNUMBER(MATCH(F25,'EQS WFD'!D:D,0)),TRUE,FALSE) -> FALSE | AJ25: =IF(ISNUMBER(MATCH(F25,'SoC_Ctgb 20181010'!C:C,0)),TRUE,FALSE) -> FALSE
M26: =IF(COUNTIF(N26:W26,TRUE)>0,TRUE,"Not Found") -> Not Found | N26: =IF(AND((COUNTIF($E$4,"*H3*")),(COUNTIF(K26,"*H3*"))),TRUE,FALSE) -> FALSE | P26: =AD26 -> FALSE | Q26: =AE26 -> FALSE | R26: =AF26 -> FALSE | T26: =AC26 -> FALSE | U26: =AD26 -> FALSE | W26: {=IF(ISBLANK(F26),"FALSE",IFERROR((VLOOKUP(TRIM(F26),TRIM(SCOEL!$B$12:$E$400),3,"FALSE")),"FALSE"))} -> FALSE | X26: =IF(COUNTIF(Z26:AI26,TRUE)>0,TRUE,"Not Found") -> Not Found | Y26: =IF(AND((COUNTIF($E$4,"*H4*")),(COUNTIF(K26,"*H4*"))),TRUE,FALSE) -> FALSE | Z26: =IF(COUNTIF(K26,"*H410*"),IF(J26*L26>25,"Cat. 1","not classified"),IF(COUNTIF(K26,"*H411*"),IF(L26>=25,"Cat. 2","not classified"),"geen H411")) -> geen H411 | AA26: =IF(ISNUMBER(MATCH(F26,'ECHA POP'!D:D,0)),TRUE,FALSE) -> FALSE | AB26: =IF(ISNUMBER(MATCH(F26,'ECHA candidate SVHC'!D:D,0)),TRUE,FALSE) -> FALSE | AC26: =IF(ISNUMBER(MATCH(F26,'ECHA PBT'!D:D,0)),TRUE,FALSE) -> FALSE | AD26: {=IF(ISNUMBER(MATCH(F26, _xlfn._xlws.FILTER('ECHA biocidal AS'!C:C, 'ECHA biocidal AS'!H:H="true"), 0)), "yes", FALSE)} -> FALSE | AE26: =IF(AND(AD26=FALSE,(ISNUMBER(MATCH(F26,'ECHA biocidal AS'!C:C,0)))),TRUE,FALSE) -> FALSE | AF26: {=IF(ISNUMBER(MATCH(F26, _xlfn._xlws.FILTER('ECHA biocidal AS'!C:C, 'ECHA biocidal AS'!M:M="Approved"), 0)), TRUE, FALSE)} -> FALSE | AH26: =IF(ISNUMBER(MATCH(F26,'EQS WFD'!D:D,0)),TRUE,FALSE) -> FALSE | AJ26: =IF(ISNUMBER(MATCH(F26,'SoC_Ctgb 20181010'!C:C,0)),TRUE,FALSE) -> FALSE
